Workbook

Sheet 1st Week
A1: Date | B1: 46204
B2: Names | C2: Amount Taken | D2: Alone plus Awar Lone Amount Gotten | E2: Grade 1 ( Aphyu Lone) Gotten | F2: Rotten | G2: Total Amount Gotten | H2: Percent % | I2: Price Rates | J2: Change From Previous Day | K2: Payroll Amount | L2: Amount Paid | M2: Change for Next Day
B3: Khin Thet Cho | C3: 8.5 | D3: 6.35 | E3: 5.56 | F3: 0.3 | G3: =C3-F3 -> 8.2 | H3: =D3/G3 -> 0.77439024 | J3: 147.5 | K3: =(G3*I3)+J3 -> 147.5 | L3: -520 | M3: =K3-L3 -> 667.5
A4: 1.07 | B4: Nu Nu Win | C4: 11.1 | D4: 8.7 | E4: 7.95 | F4: 0.36 | G4: =C4-F4 -> 10.74 | H4: =D4/G4 -> 0.81005587 | I4: 3000 | J4: 49134 | K4: =(G4*I4)+J4 -> 81354 | M4: =K4-L4 -> 81354
A5: 0.96 | B5: Mi Tayy | C5: 7.4 | D5: 5.95 | E5: 5.35 | F5: 0.15 | G5: =C5-F5 -> 7.25 | H5: =D5/G5 -> 0.82068966 | I5: 3000 | J5: 35953 | K5: =(G5*I5)+J5 -> 57703 | M5: =K5-L5 -> 57703
A6: 0.865 | B6: Kaung Khant | C6: 8.05 | D6: 6.35 | E6: 5.56 | F6: 0.3 | G6: =C6-F6 -> 7.75 | H6: =D6/G6 -> 0.81935484 | I6: 3000 | J6: 470 | K6: =(G6*I6)+J6 -> 23720 | L6: 23000 | M6: =K6-L6 -> 720
A7: 0.885 | B7: Than Cho | G7: =C7-F7 -> 0 | H7: =D7/G7 -> #DIV/0! | J7: 81 | K7: =(G7*I7)+J7 -> 81 | M7: =K7-L7 -> 81
B8: Thel Thel | C8: 14.5 | D8: 10.78 | E8: 9.68 | F8: 0.44 | G8: =C8-F8 -> 14.06 | H8: =D8/G8 -> 0.76671408 | I8: 3000 | J8: 38 | K8: =(G8*I8)+J8 -> 42218 | L8: 42000 | M8: =K8-L8 -> 218 | N8: 15
A9: 0.85 | B9: War War Tun | G9: =C9-F9 -> 0 | H9: =D9/G9 -> #DIV/0! | J9: 360 | K9: =(G9*I9)+J9 -> 360 | M9: =K9-L9 -> 360
A10: 0.93 | B10: Ma Ni Sander | G10: =C10-F10 -> 0 | H10: =D10/G10 -> #DIV/0! | J10: -275 | K10: =(G10*I10)+J10 -> -275 | M10: =K10-L10 -> -275
A11: 0.96 | B11: Khin May Sann | C11: 6.1 | D11: 4.85 | E11: 4.1 | F11: 0.1 | G11: =C11-F11 -> 6 | H11: =D11/G11 -> 0.80833333 | I11: 3000 | J11: 447 | K11: =(G11*I11)+J11 -> 18447 | L11: 18000 | M11: =K11-L11 -> 447
A12: 0.815 | B12: Naing Naing Win | G12: =C12-F12 -> 0 | H12: =D12/G12 -> #DIV/0! | J12: 649 | K12: =(G12*I12)+J12 -> 649 | M12: =K12-L12 -> 649
G13: =C13-F13 -> 0 | H13: =D13/G13 -> #DIV/0! | J13: 0 | K13: =(G13*I13)+J13 -> 0 | M13: =K13-L13 -> 0
G14: =C14-F14 -> 0 | H14: =D14/G14 -> #DIV/0! | J14: 0 | K14: =(G14*I14)+J14 -> 0 | M14: =K14-L14 -> 0
G15: =C15-F15 -> 0 | H15: =D15/G15 -> #DIV/0! | J15: 0 | K15: =(G15*I15)+J15 -> 0 | M15: =K15-L15 -> 0
G16: =C16-F16 -> 0 | H16: =D16/G16 -> #DIV/0! | J16: 0 | K16: =(G16*I16)+J16 -> 0 | M16: =K16-L16 -> 0
G17: =C17-F17 -> 0 | H17: =D17/G17 -> #DIV/0! | J17: 0 | K17: =(G17*I17)+J17 -> 0 | M17: =K17-L17 -> 0
B18: Khin Win | G18: =C18-F18 -> 0 | H18: =D18/G18 -> #DIV/0! | J18: 140350 | K18: =(G18*I18)+J18 -> 140350 | M18: =K18-L18 -> 140350
A19: Temporary | G19: =C19-F19 -> 0 | H19: =D19/G19 -> #DIV/0! | J19: 0 | K19: =(G19*I19)+J19 -> 0 | M19: =K19-L19 -> 0
D20: Total | E20: =SUM(E3:E19) -> 38.2 | K20: Total Paid | L20: =SUM(L3:L19) -> 82480
A21: Date | B21: 46205
B22: Names | C22: Amount Taken | D22: Alone plus Awar Lone Amount Gotten | E22: Grade 1 ( Aphyu Lone) Gotten | F22: Rotten | G22: Total Amount Gotten | H22: Percent % | I22: Price Rates | J22: Change From Previous Day | K22: Payroll Amount | L22: Amount Paid | M22: Change for Next Day
B23: Khin Thet Cho | C23: 8.1 | D23: 6.25 | E23: 5.8 | F23: 0.15 | G23: =C23-F23 -> 7.95 | H23: =D23/G23 -> 0.78616352 | I23: 3000 | J23: =M3 -> 667.5 | K23: =(G23*I23)+J23 -> 24517.5 | L23: 24000 | M23: =K23-L23 -> 517.5
A24: 1.07 | B24: Nu Nu Win | C24: 9.8 | D24: 7.65 | E24: 6.95 | F24: 0.2 | G24: =C24-F24 -> 9.6 | H24: =D24/G24 -> 0.796875 | I24: 3000 | J24: =M4 -> 81354 | K24: =(G24*I24)+J24 -> 110154 | M24: =K24-L24 -> 110154
A25: 0.96 | B25: Mi Tayy | C25: 7.55 | D25: 5.9 | E25: 5.5 | F25: 0.15 | G25: =C25-F25 -> 7.4 | H25: =D25/G25 -> 0.7972973 | I25: 3000 | J25: =M5 -> 57703 | K25: =(G25*I25)+J25 -> 79903 | M25: =K25-L25 -> 79903
A26: 0.865 | B26: Kaung Khant | G26: =C26-F26 -> 0 | H26: =D26/G26 -> #DIV/0! | J26: =M6 -> 720 | K26: =(G26*I26)+J26 -> 720 | M26: =K26-L26 -> 720
A27: 0.885 | B27: Than Cho | G27: =C27-F27 -> 0 | H27: =D27/G27 -> #DIV/0! | J27: =M7 -> 81 | K27: =(G27*I27)+J27 -> 81 | M27: =K27-L27 -> 81
B28: Thel Thel | G28: =C28-F28 -> 0 | H28: =D28/G28 -> #DIV/0! | J28: =M8 -> 218 | K28: =(G28*I28)+J28 -> 218 | M28: =K28-L28 -> 218
A29: 0.85 | B29: War War Tun | G29: =C29-F29 -> 0 | H29: =D29/G29 -> #DIV/0! | J29: =M9 -> 360 | K29: =(G29*I29)+J29 -> 360 | M29: =K29-L29 -> 360
A30: 0.93 | B30: Ma Ni Sander | G30: =C30-F30 -> 0 | H30: =D30/G30 -> #DIV/0! | J30: =M10 -> -275 | K30: =(G30*I30)+J30 -> -275 | M30: =K30-L30 -> -275
A31: 0.96 | B31: Khin May Sann | C31: 6.5 | D31: 5 | E31: 4.3 | F31: 0.15 | G31: =C31-F31 -> 6.35 | H31: =D31/G31 -> 0.78740157 | I31: 3000 | J31: =M11 -> 447 | K31: =(G31*I31)+J31 -> 19497 | L31: 19000 | M31: =K31-L31 -> 497
A32: 0.815 | B32: Naing Naing Win | G32: =C32-F32 -> 0 | H32: =D32/G32 -> #DIV/0! | J32: =M12 -> 649 | K32: =(G32*I32)+J32 -> 649 | M32: =K32-L32 -> 649
G33: =C33-F33 -> 0 | H33: =D33/G33 -> #DIV/0! | J33: =M13 -> 0 | K33: =(G33*I33)+J33 -> 0 | M33: =K33-L33 -> 0
G34: =C34-F34 -> 0 | H34: =D34/G34 -> #DIV/0! | J34: =M14 -> 0 | K34: =(G34*I34)+J34 -> 0 | M34: =K34-L34 -> 0
G35: =C35-F35 -> 0 | H35: =D35/G35 -> #DIV/0! | J35: =M15 -> 0 | K35: =(G35*I35)+J35 -> 0 | M35: =K35-L35 -> 0
G36: =C36-F36 -> 0 | H36: =D36/G36 -> #DIV/0! | J36: =M16 -> 0 | K36: =(G36*I36)+J36 -> 0 | M36: =K36-L36 -> 0
G37: =C37-F37 -> 0 | H37: =D37/G37 -> #DIV/0! | J37: =M17 -> 0 | K37: =(G37*I37)+J37 -> 0 | M37: =K37-L37 -> 0
B38: Khin Win | G38: =C38-F38 -> 0 | H38: =D38/G38 -> #DIV/0! | J38: =M18 -> 140350 | K38: =(G38*I38)+J38 -> 140350 | M38: =K38-L38 -> 140350
A39: Temporary | G39: =C39-F39 -> 0 | H39: =D39/G39 -> #DIV/0! | J39: =M19 -> 0 | K39: =(G39*I39)+J39 -> 0 | M39: =K39-L39 -> 0
D40: Total | E40: =SUM(E23:E39) -> 22.55 | K40: Total Paid | L40: =SUM(L23:L39) -> 43000
...

Sheet 2nd Week
A1: Date | B1: 46210
B2: Names | C2: Amount Taken | D2: Alone plus Awar Lone Amount Gotten | E2: Grade 1 ( Aphyu Lone) Gotten | F2: Rotten | G2: Total Amount Gotten | H2: Percent % | I2: Price Rates | J2: Change From Previous Day | K2: Payroll Amount | L2: Amount Paid | M2: Change for Next Day
B3: Khin Thet Cho | C3: 7.4 | D3: 5.95 | E3: 5.35 | F3: 0.15 | G3: =C3-F3 -> 7.25 | H3: =D3/G3 -> 0.82068966 | I3: 3000 | J3: ='1st Week'!M103 -> -32.5 | K3: =(G3*I3)+J3 -> 21717.5 | L3: 22000 | M3: =K3-L3 -> -282.5
A4: 1.07 | B4: Nu Nu Win | C4: 8.9 | D4: 7.1 | E4: 6.65 | F4: 0.15 | G4: =C4-F4 -> 8.75 | H4: =D4/G4 -> 0.81142857 | I4: 3000 | J4: ='1st Week'!M104 -> 41584 | K4: =(G4*I4)+J4 -> 67834 | M4: =K4-L4 -> 67834
A5: 0.96 | B5: Mi Tayy | C5: 6.5 | D5: 5.3 | E5: 5 | F5: 0.15 | G5: =C5-F5 -> 6.35 | H5: =D5/G5 -> 0.83464567 | I5: 3000 | J5: ='1st Week'!M105 -> 37153 | K5: =(G5*I5)+J5 -> 56203 | M5: =K5-L5 -> 56203
A6: 0.865 | B6: Kaung Khant | G6: =C6-F6 -> 0 | H6: =D6/G6 -> #DIV/0! | J6: ='1st Week'!M106 -> 720 | K6: =(G6*I6)+J6 -> 720 | M6: =K6-L6 -> 720
A7: 0.885 | B7: Than Cho | G7: =C7-F7 -> 0 | H7: =D7/G7 -> #DIV/0! | J7: ='1st Week'!M107 -> 81 | K7: =(G7*I7)+J7 -> 81 | M7: =K7-L7 -> 81
B8: Thel Thel | G8: =C8-F8 -> 0 | H8: =D8/G8 -> #DIV/0! | J8: ='1st Week'!M108 -> -312 | K8: =(G8*I8)+J8 -> -312 | M8: =K8-L8 -> -312
A9: 0.85 | B9: War War Tun | G9: =C9-F9 -> 0 | H9: =D9/G9 -> #DIV/0! | J9: ='1st Week'!M109 -> 360 | K9: =(G9*I9)+J9 -> 360 | M9: =K9-L9 -> 360
A10: 0.93 | B10: Ma Ni Sander | G10: =C10-F10 -> 0 | H10: =D10/G10 -> #DIV/0! | J10: ='1st Week'!M110 -> -275 | K10: =(G10*I10)+J10 -> -275 | M10: =K10-L10 -> -275
A11: 0.96 | B11: Khin May Sann | C11: 5.6 | D11: 4.5 | E11: 4.02 | F11: 0.15 | G11: =C11-F11 -> 5.45 | H11: =D11/G11 -> 0.82568807 | I11: 3000 | J11: ='1st Week'!M111 -> 17257 | K11: =(G11*I11)+J11 -> 33607 | L11: 34000 | M11: =K11-L11 -> -393
A12: 0.815 | B12: Naing Naing Win | G12: =C12-F12 -> 0 | H12: =D12/G12 -> #DIV/0! | J12: ='1st Week'!M112 -> 649 | K12: =(G12*I12)+J12 -> 649 | M12: =K12-L12 -> 649
G13: =C13-F13 -> 0 | H13: =D13/G13 -> #DIV/0! | J13: ='1st Week'!M113 -> 0 | K13: =(G13*I13)+J13 -> 0 | M13: =K13-L13 -> 0
G14: =C14-F14 -> 0 | H14: =D14/G14 -> #DIV/0! | J14: ='1st Week'!M114 -> 0 | K14: =(G14*I14)+J14 -> 0 | M14: =K14-L14 -> 0
G15: =C15-F15 -> 0 | H15: =D15/G15 -> #DIV/0! | J15: ='1st Week'!M115 -> 0 | K15: =(G15*I15)+J15 -> 0 | M15: =K15-L15 -> 0
G16: =C16-F16 -> 0 | H16: =D16/G16 -> #DIV/0! | J16: ='1st Week'!M116 -> 0 | K16: =(G16*I16)+J16 -> 0 | M16: =K16-L16 -> 0
G17: =C17-F17 -> 0 | H17: =D17/G17 -> #DIV/0! | J17: ='1st Week'!M117 -> 0 | K17: =(G17*I17)+J17 -> 0 | M17: =K17-L17 -> 0
B18: Khin Win | G18: =C18-F18 -> 0 | H18: =D18/G18 -> #DIV/0! | J18: ='1st Week'!M118 -> 218950 | K18: =(G18*I18)+J18 -> 218950 | L18: 218000 | M18: =K18-L18 -> 950
A19: Temporary | G19: =C19-F19 -> 0 | H19: =D19/G19 -> #DIV/0! | J19: ='1st Week'!M119 -> 0 | K19: =(G19*I19)+J19 -> 0 | M19: =K19-L19 -> 0
D20: Total | E20: =SUM(E3:E19) -> 21.02 | K20: Total Paid | L20: =SUM(L3:L19) -> 274000
A21: Date | B21: 46211
B22: Names | C22: Amount Taken | D22: Alone plus Awar Lone Amount Gotten | E22: Grade 1 ( Aphyu Lone) Gotten | F22: Rotten | G22: Total Amount Gotten | H22: Percent % | I22: Price Rates | J22: Change From Previous Day | K22: Payroll Amount | L22: Amount Paid | M22: Change for Next Day
B23: Khin Thet Cho | C23: 7.25 | D23: 5.8 | E23: 5.35 | F23: 0.1 | G23: =C23-F23 -> 7.15 | H23: =D23/G23 -> 0.81118881 | I23: 3000 | J23: =M3 -> -282.5 | K23: =(G23*I23)+J23 -> 21167.5 | L23: 21000 | M23: =K23-L23 -> 167.5
A24: 1.07 | B24: Nu Nu Win | C24: 6.7 | D24: 5.45 | E24: 5.04 | F24: 0.15 | G24: =C24-F24 -> 6.55 | H24: =D24/G24 -> 0.83206107 | J24: =M4 -> 67834 | K24: =(G24*I24)+J24 -> 67834 | M24: =K24-L24 -> 67834
A25: 0.96 | B25: Mi Tayy | C25: 6.5 | D25: 5.35 | E25: 4.9 | F25: 0.15 | G25: =C25-F25 -> 6.35 | H25: =D25/G25 -> 0.84251968 | J25: =M5 -> 56203 | K25: =(G25*I25)+J25 -> 56203 | M25: =K25-L25 -> 56203
A26: 0.865 | B26: Kaung Khant | G26: =C26-F26 -> 0 | H26: =D26/G26 -> #DIV/0! | J26: =M6 -> 720 | K26: =(G26*I26)+J26 -> 720 | M26: =K26-L26 -> 720
A27: 0.885 | B27: Than Cho | G27: =C27-F27 -> 0 | H27: =D27/G27 -> #DIV/0! | J27: =M7 -> 81 | K27: =(G27*I27)+J27 -> 81 | M27: =K27-L27 -> 81
B28: Thel Thel | C28: 18 | D28: 13.64 | E28: 12.44 | F28: 0.34 | G28: =C28-F28 -> 17.66 | H28: =D28/G28 -> 0.77236693 | I28: 3000 | J28: =M8 -> -312 | K28: =(G28*I28)+J28 -> 52668 | L28: 52000 | M28: =K28-L28 -> 668 | N28: 20
A29: 0.85 | B29: War War Tun | G29: =C29-F29 -> 0 | H29: =D29/G29 -> #DIV/0! | J29: =M9 -> 360 | K29: =(G29*I29)+J29 -> 360 | M29: =K29-L29 -> 360
A30: 0.93 | B30: Ma Ni Sander | G30: =C30-F30 -> 0 | H30: =D30/G30 -> #DIV/0! | J30: =M10 -> -275 | K30: =(G30*I30)+J30 -> -275 | M30: =K30-L30 -> -275
A31: 0.96 | B31: Khin May Sann | C31: 6 | D31: 4.9 | E31: 4.5 | F31: 0.15 | G31: =C31-F31 -> 5.85 | H31: =D31/G31 -> 0.83760684 | I31: 3000 | J31: =M11 -> -393 | K31: =(G31*I31)+J31 -> 17157 | L31: 17000 | M31: =K31-L31 -> 157
A32: 0.815 | B32: Naing Naing Win | G32: =C32-F32 -> 0 | H32: =D32/G32 -> #DIV/0! | J32: =M12 -> 649 | K32: =(G32*I32)+J32 -> 649 | M32: =K32-L32 -> 649
G33: =C33-F33 -> 0 | H33: =D33/G33 -> #DIV/0! | J33: =M13 -> 0 | K33: =(G33*I33)+J33 -> 0 | M33: =K33-L33 -> 0
G34: =C34-F34 -> 0 | H34: =D34/G34 -> #DIV/0! | J34: =M14 -> 0 | K34: =(G34*I34)+J34 -> 0 | M34: =K34-L34 -> 0
G35: =C35-F35 -> 0 | H35: =D35/G35 -> #DIV/0! | J35: =M15 -> 0 | K35: =(G35*I35)+J35 -> 0 | M35: =K35-L35 -> 0
G36: =C36-F36 -> 0 | H36: =D36/G36 -> #DIV/0! | J36: =M16 -> 0 | K36: =(G36*I36)+J36 -> 0 | M36: =K36-L36 -> 0
G37: =C37-F37 -> 0 | H37: =D37/G37 -> #DIV/0! | J37: =M17 -> 0 | K37: =(G37*I37)+J37 -> 0 | M37: =K37-L37 -> 0
B38: Khin Win | C38: 27 | D38: 21.7 | E38: 19.5 | F38: 0.45 | G38: =C38-F38 -> 26.55 | H38: =D38/G38 -> 0.8173258 | I38: 3000 | J38: =M18 -> 950 | K38: =(G38*I38)+J38 -> 80600 | M38: =K38-L38 -> 80600 | N38: 27 | O38: alone
A39: Temporary | G39: =C39-F39 -> 0 | H39: =D39/G39 -> #DIV/0! | J39: =M19 -> 0 | K39: =(G39*I39)+J39 -> 0 | M39: =K39-L39 -> 0
D40: Total | E40: =SUM(E23:E39) -> 51.73 | K40: Total Paid | L40: =SUM(L23:L39) -> 90000
...

Sheet 3rd Week
A1: Date
B2: Names | C2: Amount Taken | D2: Alone plus Awar Lone Amount Gotten | E2: Grade 1 ( Aphyu Lone) Gotten | F2: Rotten | G2: Total Amount Gotten | H2: Percent % | I2: Price Rates | J2: Change From Previous Day | K2: Payroll Amount | L2: Amount Paid | M2: Change for Next Day
B3: Khin Thet Cho | G3: =C3-F3 -> 0 | H3: =D3/G3 -> #DIV/0! | J3: ='2nd Week'!M123 -> 367.5 | K3: =(G3*I3)+J3 -> 367.5 | M3: =K3-L3 -> 367.5
A4: 1.07 | B4: Nu Nu Win | G4: =C4-F4 -> 0 | H4: =D4/G4 -> #DIV/0! | J4: ='2nd Week'!M124 -> 85684 | K4: =(G4*I4)+J4 -> 85684 | M4: =K4-L4 -> 85684
A5: 0.96 | B5: Mi Tayy | G5: =C5-F5 -> 0 | H5: =D5/G5 -> #DIV/0! | J5: ='2nd Week'!M125 -> 72253 | K5: =(G5*I5)+J5 -> 72253 | M5: =K5-L5 -> 72253
A6: 0.865 | B6: Kaung Khant | G6: =C6-F6 -> 0 | H6: =D6/G6 -> #DIV/0! | J6: ='2nd Week'!M126 -> 720 | K6: =(G6*I6)+J6 -> 720 | M6: =K6-L6 -> 720
A7: 0.885 | B7: Than Cho | G7: =C7-F7 -> 0 | H7: =D7/G7 -> #DIV/0! | J7: ='2nd Week'!M127 -> 81 | K7: =(G7*I7)+J7 -> 81 | M7: =K7-L7 -> 81
B8: Thel Thel | G8: =C8-F8 -> 0 | H8: =D8/G8 -> #DIV/0! | J8: ='2nd Week'!M128 -> 668 | K8: =(G8*I8)+J8 -> 668 | M8: =K8-L8 -> 668
A9: 0.85 | B9: War War Tun | G9: =C9-F9 -> 0 | H9: =D9/G9 -> #DIV/0! | J9: ='2nd Week'!M129 -> 360 | K9: =(G9*I9)+J9 -> 360 | M9: =K9-L9 -> 360
A10: 0.93 | B10: Ma Ni Sander | G10: =C10-F10 -> 0 | H10: =D10/G10 -> #DIV/0! | J10: ='2nd Week'!M130 -> -275 | K10: =(G10*I10)+J10 -> -275 | M10: =K10-L10 -> -275
A11: 0.96 | B11: Khin May Sann | G11: =C11-F11 -> 0 | H11: =D11/G11 -> #DIV/0! | J11: ='2nd Week'!M131 -> 7 | K11: =(G11*I11)+J11 -> 7 | M11: =K11-L11 -> 7
A12: 0.815 | B12: Naing Naing Win | G12: =C12-F12 -> 0 | H12: =D12/G12 -> #DIV/0! | J12: ='2nd Week'!M132 -> 649 | K12: =(G12*I12)+J12 -> 649 | M12: =K12-L12 -> 649
G13: =C13-F13 -> 0 | H13: =D13/G13 -> #DIV/0! | J13: ='2nd Week'!M133 -> 0 | K13: =(G13*I13)+J13 -> 0 | M13: =K13-L13 -> 0
G14: =C14-F14 -> 0 | H14: =D14/G14 -> #DIV/0! | J14: ='2nd Week'!M134 -> 0 | K14: =(G14*I14)+J14 -> 0 | M14: =K14-L14 -> 0
G15: =C15-F15 -> 0 | H15: =D15/G15 -> #DIV/0! | J15: ='2nd Week'!M135 -> 0 | K15: =(G15*I15)+J15 -> 0 | M15: =K15-L15 -> 0
G16: =C16-F16 -> 0 | H16: =D16/G16 -> #DIV/0! | J16: ='2nd Week'!M136 -> 0 | K16: =(G16*I16)+J16 -> 0 | M16: =K16-L16 -> 0
G17: =C17-F17 -> 0 | H17: =D17/G17 -> #DIV/0! | J17: ='2nd Week'!M137 -> 0 | K17: =(G17*I17)+J17 -> 0 | M17: =K17-L17 -> 0
B18: Khin Win | G18: =C18-F18 -> 0 | H18: =D18/G18 -> #DIV/0! | J18: ='2nd Week'!M138 -> 80600 | K18: =(G18*I18)+J18 -> 80600 | M18: =K18-L18 -> 80600
A19: Temporary | G19: =C19-F19 -> 0 | H19: =D19/G19 -> #DIV/0! | J19: ='2nd Week'!M139 -> 0 | K19: =(G19*I19)+J19 -> 0 | M19: =K19-L19 -> 0
D20: Total | E20: =SUM(E3:E19) -> 0 | K20: Total Paid | L20: =SUM(L3:L19) -> 0
A21: Date
B22: Names | C22: Amount Taken | D22: Alone plus Awar Lone Amount Gotten | E22: Grade 1 ( Aphyu Lone) Gotten | F22: Rotten | G22: Total Amount Gotten | H22: Percent % | I22: Price Rates | J22: Change From Previous Day | K22: Payroll Amount | L22: Amount Paid | M22: Change for Next Day
B23: Khin Thet Cho | G23: =C23-F23 -> 0 | H23: =D23/G23 -> #DIV/0! | J23: =M3 -> 367.5 | K23: =(G23*I23)+J23 -> 367.5 | M23: =K23-L23 -> 367.5
A24: 1.07 | B24: Nu Nu Win | G24: =C24-F24 -> 0 | H24: =D24/G24 -> #DIV/0! | J24: =M4 -> 85684 | K24: =(G24*I24)+J24 -> 85684 | M24: =K24-L24 -> 85684
A25: 0.96 | B25: Mi Tayy | G25: =C25-F25 -> 0 | H25: =D25/G25 -> #DIV/0! | J25: =M5 -> 72253 | K25: =(G25*I25)+J25 -> 72253 | M25: =K25-L25 -> 72253
A26: 0.865 | B26: Kaung Khant | G26: =C26-F26 -> 0 | H26: =D26/G26 -> #DIV/0! | J26: =M6 -> 720 | K26: =(G26*I26)+J26 -> 720 | M26: =K26-L26 -> 720
A27: 0.885 | B27: Than Cho | G27: =C27-F27 -> 0 | H27: =D27/G27 -> #DIV/0! | J27: =M7 -> 81 | K27: =(G27*I27)+J27 -> 81 | M27: =K27-L27 -> 81
B28: Thel Thel | G28: =C28-F28 -> 0 | H28: =D28/G28 -> #DIV/0! | J28: =M8 -> 668 | K28: =(G28*I28)+J28 -> 668 | M28: =K28-L28 -> 668
A29: 0.85 | B29: War War Tun | G29: =C29-F29 -> 0 | H29: =D29/G29 -> #DIV/0! | J29: =M9 -> 360 | K29: =(G29*I29)+J29 -> 360 | M29: =K29-L29 -> 360
A30: 0.93 | B30: Ma Ni Sander | G30: =C30-F30 -> 0 | H30: =D30/G30 -> #DIV/0! | J30: =M10 -> -275 | K30: =(G30*I30)+J30 -> -275 | M30: =K30-L30 -> -275
A31: 0.96 | B31: Khin May Sann | G31: =C31-F31 -> 0 | H31: =D31/G31 -> #DIV/0! | J31: =M11 -> 7 | K31: =(G31*I31)+J31 -> 7 | M31: =K31-L31 -> 7
A32: 0.815 | B32: Naing Naing Win | G32: =C32-F32 -> 0 | H32: =D32/G32 -> #DIV/0! | J32: =M12 -> 649 | K32: =(G32*I32)+J32 -> 649 | M32: =K32-L32 -> 649
G33: =C33-F33 -> 0 | H33: =D33/G33 -> #DIV/0! | J33: =M13 -> 0 | K33: =(G33*I33)+J33 -> 0 | M33: =K33-L33 -> 0
G34: =C34-F34 -> 0 | H34: =D34/G34 -> #DIV/0! | J34: =M14 -> 0 | K34: =(G34*I34)+J34 -> 0 | M34: =K34-L34 -> 0
G35: =C35-F35 -> 0 | H35: =D35/G35 -> #DIV/0! | J35: =M15 -> 0 | K35: =(G35*I35)+J35 -> 0 | M35: =K35-L35 -> 0
G36: =C36-F36 -> 0 | H36: =D36/G36 -> #DIV/0! | J36: =M16 -> 0 | K36: =(G36*I36)+J36 -> 0 | M36: =K36-L36 -> 0
G37: =C37-F37 -> 0 | H37: =D37/G37 -> #DIV/0! | J37: =M17 -> 0 | K37: =(G37*I37)+J37 -> 0 | M37: =K37-L37 -> 0
B38: Khin Win | G38: =C38-F38 -> 0 | H38: =D38/G38 -> #DIV/0! | J38: =M18 -> 80600 | K38: =(G38*I38)+J38 -> 80600 | M38: =K38-L38 -> 80600
A39: Temporary | G39: =C39-F39 -> 0 | H39: =D39/G39 -> #DIV/0! | J39: =M19 -> 0 | K39: =(G39*I39)+J39 -> 0 | M39: =K39-L39 -> 0
D40: Total | E40: =SUM(E23:E39) -> 0 | K40: Total Paid | L40: =SUM(L23:L39) -> 0
...

Sheet 4th Week
A1: Date
B2: Names | C2: Amount Taken | D2: Alone plus Awar Lone Amount Gotten | E2: Grade 1 ( Aphyu Lone) Gotten | F2: Rotten | G2: Total Amount Gotten | H2: Percent % | I2: Price Rates | J2: Change From Previous Day | K2: Payroll Amount | L2: Amount Paid | M2: Change for Next Day
B3: Khin Thet Cho | G3: =C3-F3 -> 0 | H3: =D3/G3 -> #DIV/0! | J3: ='3rd Week'!M123 -> 367.5 | K3: =(G3*I3)+J3 -> 367.5 | M3: =K3-L3 -> 367.5
A4: 1.07 | B4: Nu Nu Win | G4: =C4-F4 -> 0 | H4: =D4/G4 -> #DIV/0! | J4: ='3rd Week'!M124 -> 85684 | K4: =(G4*I4)+J4 -> 85684 | M4: =K4-L4 -> 85684
A5: 0.96 | B5: Mi Tayy | G5: =C5-F5 -> 0 | H5: =D5/G5 -> #DIV/0! | J5: ='3rd Week'!M125 -> 72253 | K5: =(G5*I5)+J5 -> 72253 | M5: =K5-L5 -> 72253
A6: 0.865 | B6: Kaung Khant | G6: =C6-F6 -> 0 | H6: =D6/G6 -> #DIV/0! | J6: ='3rd Week'!M126 -> 720 | K6: =(G6*I6)+J6 -> 720 | M6: =K6-L6 -> 720
A7: 0.885 | B7: Than Cho | G7: =C7-F7 -> 0 | H7: =D7/G7 -> #DIV/0! | J7: ='3rd Week'!M127 -> 81 | K7: =(G7*I7)+J7 -> 81 | M7: =K7-L7 -> 81
B8: Thel Thel | G8: =C8-F8 -> 0 | H8: =D8/G8 -> #DIV/0! | J8: ='3rd Week'!M128 -> 668 | K8: =(G8*I8)+J8 -> 668 | M8: =K8-L8 -> 668
A9: 0.85 | B9: War War Tun | G9: =C9-F9 -> 0 | H9: =D9/G9 -> #DIV/0! | J9: ='3rd Week'!M129 -> 360 | K9: =(G9*I9)+J9 -> 360 | M9: =K9-L9 -> 360
A10: 0.93 | B10: Ma Ni Sander | G10: =C10-F10 -> 0 | H10: =D10/G10 -> #DIV/0! | J10: ='3rd Week'!M130 -> -275 | K10: =(G10*I10)+J10 -> -275 | M10: =K10-L10 -> -275
A11: 0.96 | B11: Khin May Sann | G11: =C11-F11 -> 0 | H11: =D11/G11 -> #DIV/0! | J11: ='3rd Week'!M131 -> 7 | K11: =(G11*I11)+J11 -> 7 | M11: =K11-L11 -> 7
A12: 0.815 | B12: Naing Naing Win | G12: =C12-F12 -> 0 | H12: =D12/G12 -> #DIV/0! | J12: ='3rd Week'!M132 -> 649 | K12: =(G12*I12)+J12 -> 649 | M12: =K12-L12 -> 649
G13: =C13-F13 -> 0 | H13: =D13/G13 -> #DIV/0! | J13: ='3rd Week'!M133 -> 0 | K13: =(G13*I13)+J13 -> 0 | M13: =K13-L13 -> 0
G14: =C14-F14 -> 0 | H14: =D14/G14 -> #DIV/0! | J14: ='3rd Week'!M134 -> 0 | K14: =(G14*I14)+J14 -> 0 | M14: =K14-L14 -> 0
G15: =C15-F15 -> 0 | H15: =D15/G15 -> #DIV/0! | J15: ='3rd Week'!M135 -> 0 | K15: =(G15*I15)+J15 -> 0 | M15: =K15-L15 -> 0
G16: =C16-F16 -> 0 | H16: =D16/G16 -> #DIV/0! | J16: ='3rd Week'!M136 -> 0 | K16: =(G16*I16)+J16 -> 0 | M16: =K16-L16 -> 0
G17: =C17-F17 -> 0 | H17: =D17/G17 -> #DIV/0! | J17: ='3rd Week'!M137 -> 0 | K17: =(G17*I17)+J17 -> 0 | M17: =K17-L17 -> 0
B18: Khin Win | G18: =C18-F18 -> 0 | H18: =D18/G18 -> #DIV/0! | J18: ='3rd Week'!M138 -> 80600 | K18: =(G18*I18)+J18 -> 80600 | M18: =K18-L18 -> 80600
A19: Temporary | G19: =C19-F19 -> 0 | H19: =D19/G19 -> #DIV/0! | J19: ='3rd Week'!M139 -> 0 | K19: =(G19*I19)+J19 -> 0 | M19: =K19-L19 -> 0
D20: Total | E20: =SUM(E3:E19) -> 0 | K20: Total Paid | L20: =SUM(L3:L19) -> 0
A21: Date
B22: Names | C22: Amount Taken | D22: Alone plus Awar Lone Amount Gotten | E22: Grade 1 ( Aphyu Lone) Gotten | F22: Rotten | G22: Total Amount Gotten | H22: Percent % | I22: Price Rates | J22: Change From Previous Day | K22: Payroll Amount | L22: Amount Paid | M22: Change for Next Day
B23: Khin Thet Cho | G23: =C23-F23 -> 0 | H23: =D23/G23 -> #DIV/0! | J23: =M3 -> 367.5 | K23: =(G23*I23)+J23 -> 367.5 | M23: =K23-L23 -> 367.5
A24: 1.07 | B24: Nu Nu Win | G24: =C24-F24 -> 0 | H24: =D24/G24 -> #DIV/0! | J24: =M4 -> 85684 | K24: =(G24*I24)+J24 -> 85684 | M24: =K24-L24 -> 85684
A25: 0.96 | B25: Mi Tayy | G25: =C25-F25 -> 0 | H25: =D25/G25 -> #DIV/0! | J25: =M5 -> 72253 | K25: =(G25*I25)+J25 -> 72253 | M25: =K25-L25 -> 72253
A26: 0.865 | B26: Kaung Khant | G26: =C26-F26 -> 0 | H26: =D26/G26 -> #DIV/0! | J26: =M6 -> 720 | K26: =(G26*I26)+J26 -> 720 | M26: =K26-L26 -> 720
A27: 0.885 | B27: Than Cho | G27: =C27-F27 -> 0 | H27: =D27/G27 -> #DIV/0! | J27: =M7 -> 81 | K27: =(G27*I27)+J27 -> 81 | M27: =K27-L27 -> 81
B28: Thel Thel | G28: =C28-F28 -> 0 | H28: =D28/G28 -> #DIV/0! | J28: =M8 -> 668 | K28: =(G28*I28)+J28 -> 668 | M28: =K28-L28 -> 668
A29: 0.85 | B29: War War Tun | G29: =C29-F29 -> 0 | H29: =D29/G29 -> #DIV/0! | J29: =M9 -> 360 | K29: =(G29*I29)+J29 -> 360 | M29: =K29-L29 -> 360
A30: 0.93 | B30: Ma Ni Sander | G30: =C30-F30 -> 0 | H30: =D30/G30 -> #DIV/0! | J30: =M10 -> -275 | K30: =(G30*I30)+J30 -> -275 | M30: =K30-L30 -> -275
A31: 0.96 | B31: Khin May Sann | G31: =C31-F31 -> 0 | H31: =D31/G31 -> #DIV/0! | J31: =M11 -> 7 | K31: =(G31*I31)+J31 -> 7 | M31: =K31-L31 -> 7
A32: 0.815 | B32: Naing Naing Win | G32: =C32-F32 -> 0 | H32: =D32/G32 -> #DIV/0! | J32: =M12 -> 649 | K32: =(G32*I32)+J32 -> 649 | M32: =K32-L32 -> 649
G33: =C33-F33 -> 0 | H33: =D33/G33 -> #DIV/0! | J33: =M13 -> 0 | K33: =(G33*I33)+J33 -> 0 | M33: =K33-L33 -> 0
G34: =C34-F34 -> 0 | H34: =D34/G34 -> #DIV/0! | J34: =M14 -> 0 | K34: =(G34*I34)+J34 -> 0 | M34: =K34-L34 -> 0
G35: =C35-F35 -> 0 | H35: =D35/G35 -> #DIV/0! | J35: =M15 -> 0 | K35: =(G35*I35)+J35 -> 0 | M35: =K35-L35 -> 0
G36: =C36-F36 -> 0 | H36: =D36/G36 -> #DIV/0! | J36: =M16 -> 0 | K36: =(G36*I36)+J36 -> 0 | M36: =K36-L36 -> 0
G37: =C37-F37 -> 0 | H37: =D37/G37 -> #DIV/0! | J37: =M17 -> 0 | K37: =(G37*I37)+J37 -> 0 | M37: =K37-L37 -> 0
B38: Khin Win | G38: =C38-F38 -> 0 | H38: =D38/G38 -> #DIV/0! | J38: =M18 -> 80600 | K38: =(G38*I38)+J38 -> 80600 | M38: =K38-L38 -> 80600
A39: Temporary | G39: =C39-F39 -> 0 | H39: =D39/G39 -> #DIV/0! | J39: =M19 -> 0 | K39: =(G39*I39)+J39 -> 0 | M39: =K39-L39 -> 0
D40: Total | E40: =SUM(E23:E39) -> 0 | K40: Total Paid | L40: =SUM(L23:L39) -> 0
...
